2025-08-20 20:20:13,514 [INFO] Step-1: Folder created: /Users/aditiprasad/Desktop/tds-2/uploads/a00ffe63-de98-4e4f-a01e-717656dd06bc
2025-08-20 20:20:13,517 [INFO] Using Python executable: /Users/aditiprasad/Desktop/tds-2/venv/bin/python3
2025-08-20 20:20:13,517 [INFO] ü§ñ Step-1: Getting initial code from LLM. Attempt 1
2025-08-20 20:20:29,967 [INFO] ü§ñ Step-1: Successfully parsed response from LLM.
2025-08-20 20:20:29,968 [INFO] üíª Loop-1: Running LLM-generated code.
2025-08-20 20:20:30,707 [ERROR] ‚ùåüíª Loop-1: Code execution failed: Traceback (most recent call last): File "/Users/aditiprasad/Desktop/tds-2/venv/lib/python3.13/site-packages/pandas/core/indexes/base.py", line 3812, in get_loc return self._engine.get_loc(casted_key) ~~~~~~~~~~~~~~~~~~~~^^^^^^^^^^^^ File "pandas/_libs/index.pyx", line 167, in pandas._libs.index.IndexEngine.get_loc File "pandas/_libs/index.pyx", line 196, in pandas._libs.index.IndexEngine.get_loc File "pandas/_libs/hashtable_class_helper.pxi", line 7088, in pandas._libs.hashtable.PyObjectHashTable.get_item File "pandas/_libs/hashtable_class_helper.pxi", line 7096, in pandas._libs.hashtable.PyObjectHashTable.get_item KeyError: 'precipitation_mm' The above exception was the direct cause of the following exception: Traceback (most recent call last): File "/Users/aditiprasad/Desktop/tds-2/uploads/a00ffe63-de98-4e4f-a01e-717656dd06bc/script.py", line 15, in <module> max_precip_date = df.loc[df['precipitation_mm'].idxmax(), 'date'].strftime('%Y-%m-%d') ~~^^^^^^^^^^^^^^^^^^^^ File "/Users/aditiprasad/Desktop/tds-2/venv/lib/python3.13/site-packages/pandas/core/frame.py", line 4107, in __getitem__ indexer = self.columns.get_loc(key) File "/Users/aditiprasad/Desktop/tds-2/venv/lib/python3.13/site-packages/pandas/core/indexes/base.py", line 3819, in get_loc raise KeyError(key) from err KeyError: 'precipitation_mm'
2025-08-20 20:20:30,707 [INFO] ü§ñ Loop-1: Getting next step from LLM. Attempt 1
2025-08-20 20:20:38,599 [INFO] üíª Loop-2: Running LLM-generated code.
2025-08-20 20:20:39,208 [ERROR] ‚ùåüíª Loop-2: Code execution failed: Traceback (most recent call last): File "/Users/aditiprasad/Desktop/tds-2/venv/lib/python3.13/site-packages/pandas/core/indexes/base.py", line 3812, in get_loc return self._engine.get_loc(casted_key) ~~~~~~~~~~~~~~~~~~~~^^^^^^^^^^^^ File "pandas/_libs/index.pyx", line 167, in pandas._libs.index.IndexEngine.get_loc File "pandas/_libs/index.pyx", line 196, in pandas._libs.index.IndexEngine.get_loc File "pandas/_libs/hashtable_class_helper.pxi", line 7088, in pandas._libs.hashtable.PyObjectHashTable.get_item File "pandas/_libs/hashtable_class_helper.pxi", line 7096, in pandas._libs.hashtable.PyObjectHashTable.get_item KeyError: 'precipitation' The above exception was the direct cause of the following exception: Traceback (most recent call last): File "/Users/aditiprasad/Desktop/tds-2/uploads/a00ffe63-de98-4e4f-a01e-717656dd06bc/script.py", line 15, in <module> max_precip_date = df.loc[df['precipitation'].idxmax(), 'date'].strftime('%Y-%m-%d') ~~^^^^^^^^^^^^^^^^^ File "/Users/aditiprasad/Desktop/tds-2/venv/lib/python3.13/site-packages/pandas/core/frame.py", line 4107, in __getitem__ indexer = self.columns.get_loc(key) File "/Users/aditiprasad/Desktop/tds-2/venv/lib/python3.13/site-packages/pandas/core/indexes/base.py", line 3819, in get_loc raise KeyError(key) from err KeyError: 'precipitation'
2025-08-20 20:20:39,208 [INFO] ü§ñ Loop-2: Getting next step from LLM. Attempt 1
2025-08-20 20:20:46,721 [INFO] üíª Loop-3: Running LLM-generated code.
2025-08-20 20:20:47,339 [ERROR] ‚ùåüíª Loop-3: Code execution failed: Traceback (most recent call last): File "/Users/aditiprasad/Desktop/tds-2/venv/lib/python3.13/site-packages/pandas/core/indexes/base.py", line 3812, in get_loc return self._engine.get_loc(casted_key) ~~~~~~~~~~~~~~~~~~~~^^^^^^^^^^^^ File "pandas/_libs/index.pyx", line 167, in pandas._libs.index.IndexEngine.get_loc File "pandas/_libs/index.pyx", line 196, in pandas._libs.index.IndexEngine.get_loc File "pandas/_libs/hashtable_class_helper.pxi", line 7088, in pandas._libs.hashtable.PyObjectHashTable.get_item File "pandas/_libs/hashtable_class_helper.pxi", line 7096, in pandas._libs.hashtable.PyObjectHashTable.get_item KeyError: 'precipitation_mm' The above exception was the direct cause of the following exception: Traceback (most recent call last): File "/Users/aditiprasad/Desktop/tds-2/uploads/a00ffe63-de98-4e4f-a01e-717656dd06bc/script.py", line 15, in <module> max_precip_date = df.loc[df['precipitation_mm'].idxmax(), 'date'].strftime('%Y-%m-%d') ~~^^^^^^^^^^^^^^^^^^^^ File "/Users/aditiprasad/Desktop/tds-2/venv/lib/python3.13/site-packages/pandas/core/frame.py", line 4107, in __getitem__ indexer = self.columns.get_loc(key) File "/Users/aditiprasad/Desktop/tds-2/venv/lib/python3.13/site-packages/pandas/core/indexes/base.py", line 3819, in get_loc raise KeyError(key) from err KeyError: 'precipitation_mm'
2025-08-20 20:20:47,339 [INFO] ü§ñ Loop-3: Getting next step from LLM. Attempt 1
2025-08-20 20:20:54,671 [INFO] üíª Loop-4: Running LLM-generated code.
2025-08-20 20:20:55,276 [ERROR] ‚ùåüíª Loop-4: Code execution failed: Traceback (most recent call last): File "/Users/aditiprasad/Desktop/tds-2/venv/lib/python3.13/site-packages/pandas/core/indexes/base.py", line 3812, in get_loc return self._engine.get_loc(casted_key) ~~~~~~~~~~~~~~~~~~~~^^^^^^^^^^^^ File "pandas/_libs/index.pyx", line 167, in pandas._libs.index.IndexEngine.get_loc File "pandas/_libs/index.pyx", line 196, in pandas._libs.index.IndexEngine.get_loc File "pandas/_libs/hashtable_class_helper.pxi", line 7088, in pandas._libs.hashtable.PyObjectHashTable.get_item File "pandas/_libs/hashtable_class_helper.pxi", line 7096, in pandas._libs.hashtable.PyObjectHashTable.get_item KeyError: 'precipitation_mm' The above exception was the direct cause of the following exception: Traceback (most recent call last): File "/Users/aditiprasad/Desktop/tds-2/uploads/a00ffe63-de98-4e4f-a01e-717656dd06bc/script.py", line 15, in <module> max_precip_date = df.loc[df['precipitation_mm'].idxmax(), 'date'].strftime('%Y-%m-%d') ~~^^^^^^^^^^^^^^^^^^^^ File "/Users/aditiprasad/Desktop/tds-2/venv/lib/python3.13/site-packages/pandas/core/frame.py", line 4107, in __getitem__ indexer = self.columns.get_loc(key) File "/Users/aditiprasad/Desktop/tds-2/venv/lib/python3.13/site-packages/pandas/core/indexes/base.py", line 3819, in get_loc raise KeyError(key) from err KeyError: 'precipitation_mm'
2025-08-20 20:20:55,277 [INFO] ü§ñ Loop-4: Getting next step from LLM. Attempt 1
2025-08-20 20:21:02,940 [INFO] üíª Loop-5: Running LLM-generated code.
2025-08-20 20:21:03,558 [ERROR] ‚ùåüíª Loop-5: Code execution failed: Traceback (most recent call last): File "/Users/aditiprasad/Desktop/tds-2/venv/lib/python3.13/site-packages/pandas/core/indexes/base.py", line 3812, in get_loc return self._engine.get_loc(casted_key) ~~~~~~~~~~~~~~~~~~~~^^^^^^^^^^^^ File "pandas/_libs/index.pyx", line 167, in pandas._libs.index.IndexEngine.get_loc File "pandas/_libs/index.pyx", line 196, in pandas._libs.index.IndexEngine.get_loc File "pandas/_libs/hashtable_class_helper.pxi", line 7088, in pandas._libs.hashtable.PyObjectHashTable.get_item File "pandas/_libs/hashtable_class_helper.pxi", line 7096, in pandas._libs.hashtable.PyObjectHashTable.get_item KeyError: 'precipitation_mm' The above exception was the direct cause of the following exception: Traceback (most recent call last): File "/Users/aditiprasad/Desktop/tds-2/uploads/a00ffe63-de98-4e4f-a01e-717656dd06bc/script.py", line 15, in <module> max_precip_date = df.loc[df['precipitation_mm'].idxmax(), 'date'].strftime('%Y-%m-%d') ~~^^^^^^^^^^^^^^^^^^^^ File "/Users/aditiprasad/Desktop/tds-2/venv/lib/python3.13/site-packages/pandas/core/frame.py", line 4107, in __getitem__ indexer = self.columns.get_loc(key) File "/Users/aditiprasad/Desktop/tds-2/venv/lib/python3.13/site-packages/pandas/core/indexes/base.py", line 3819, in get_loc raise KeyError(key) from err KeyError: 'precipitation_mm'
2025-08-20 20:21:03,559 [INFO] ü§ñ Loop-5: Getting next step from LLM. Attempt 1
