2025-08-20 20:26:01,167 [INFO] Step-1: Folder created: /Users/aditiprasad/Desktop/tds-2/uploads/e8c70522-ee5b-42be-ba62-46e029d05ffc
2025-08-20 20:26:01,169 [INFO] Using Python executable: /Users/aditiprasad/Desktop/tds-2/venv/bin/python3
2025-08-20 20:26:01,169 [INFO] ü§ñ Step-1: Getting initial code from LLM. Attempt 1
2025-08-20 20:26:15,929 [INFO] ü§ñ Step-1: Successfully parsed response from LLM.
2025-08-20 20:26:15,929 [INFO] üíª Loop-1: Running LLM-generated code.
2025-08-20 20:26:19,631 [ERROR] ‚ùåüíª Loop-1: Code execution failed: Traceback (most recent call last): File "/Users/aditiprasad/Desktop/tds-2/venv/lib/python3.13/site-packages/pandas/core/indexes/base.py", line 3812, in get_loc return self._engine.get_loc(casted_key) ~~~~~~~~~~~~~~~~~~~~^^^^^^^^^^^^ File "pandas/_libs/index.pyx", line 167, in pandas._libs.index.IndexEngine.get_loc File "pandas/_libs/index.pyx", line 196, in pandas._libs.index.IndexEngine.get_loc File "pandas/_libs/hashtable_class_helper.pxi", line 7088, in pandas._libs.hashtable.PyObjectHashTable.get_item File "pandas/_libs/hashtable_class_helper.pxi", line 7096, in pandas._libs.hashtable.PyObjectHashTable.get_item KeyError: 'precipitation_mm' The above exception was the direct cause of the following exception: Traceback (most recent call last): File "/Users/aditiprasad/Desktop/tds-2/uploads/e8c70522-ee5b-42be-ba62-46e029d05ffc/script.py", line 19, in <module> max_precip_date = df.loc[df['precipitation_mm'].idxmax(), 'date'] ~~^^^^^^^^^^^^^^^^^^^^ File "/Users/aditiprasad/Desktop/tds-2/venv/lib/python3.13/site-packages/pandas/core/frame.py", line 4107, in __getitem__ indexer = self.columns.get_loc(key) File "/Users/aditiprasad/Desktop/tds-2/venv/lib/python3.13/site-packages/pandas/core/indexes/base.py", line 3819, in get_loc raise KeyError(key) from err KeyError: 'precipitation_mm'
2025-08-20 20:26:19,631 [INFO] ü§ñ Loop-1: Getting next step from LLM. Attempt 1
2025-08-20 20:26:31,139 [INFO] üíª Loop-2: Running LLM-generated code.
2025-08-20 20:26:31,977 [ERROR] ‚ùåüíª Loop-2: Code execution failed: Traceback (most recent call last): File "/Users/aditiprasad/Desktop/tds-2/uploads/e8c70522-ee5b-42be-ba62-46e029d05ffc/script.py", line 40, in <module> temp_image = temp_chart.canvas.tostring_rgb() ^^^^^^^^^^^^^^^^^^^^^^^^^^^^^^ AttributeError: 'FigureCanvasMac' object has no attribute 'tostring_rgb'. Did you mean: 'tostring_argb'?
2025-08-20 20:26:31,978 [INFO] ü§ñ Loop-2: Getting next step from LLM. Attempt 1
2025-08-20 20:26:43,221 [INFO] üíª Loop-3: Running LLM-generated code.
2025-08-20 20:26:44,135 [ERROR] ‚ùåüíª Loop-3: Code execution failed: Traceback (most recent call last): File "/Users/aditiprasad/Desktop/tds-2/uploads/e8c70522-ee5b-42be-ba62-46e029d05ffc/script.py", line 73, in <module> json.dump(result, f) ~~~~~~~~~^^^^^^^^^^^ File "/opt/homebrew/Cellar/python@3.13/3.13.5/Frameworks/Python.framework/Versions/3.13/lib/python3.13/json/__init__.py", line 179, in dump for chunk in iterable: ^^^^^^^^ File "/opt/homebrew/Cellar/python@3.13/3.13.5/Frameworks/Python.framework/Versions/3.13/lib/python3.13/json/encoder.py", line 433, in _iterencode yield from _iterencode_dict(o, _current_indent_level) File "/opt/homebrew/Cellar/python@3.13/3.13.5/Frameworks/Python.framework/Versions/3.13/lib/python3.13/json/encoder.py", line 407, in _iterencode_dict yield from chunks File "/opt/homebrew/Cellar/python@3.13/3.13.5/Frameworks/Python.framework/Versions/3.13/lib/python3.13/json/encoder.py", line 440, in _iterencode o = _default(o) File "/opt/homebrew/Cellar/python@3.13/3.13.5/Frameworks/Python.framework/Versions/3.13/lib/python3.13/json/encoder.py", line 180, in default raise TypeError(f'Object of type {o.__class__.__name__} ' f'is not JSON serializable') TypeError: Object of type int64 is not JSON serializable
2025-08-20 20:26:44,135 [INFO] ‚úÖüìÅ Loop-3: Found result.json. Verifying...
2025-08-20 20:26:44,135 [INFO] ü§ñ Loop-3: Getting next step from LLM. Attempt 1
2025-08-20 20:26:53,802 [INFO] üíª Loop-4: Running LLM-generated code.
2025-08-20 20:26:54,688 [ERROR] ‚ùåüíª Loop-4: Code execution failed: Traceback (most recent call last): File "/Users/aditiprasad/Desktop/tds-2/uploads/e8c70522-ee5b-42be-ba62-46e029d05ffc/script.py", line 69, in <module> json.dump(result, f) ~~~~~~~~~^^^^^^^^^^^ File "/opt/homebrew/Cellar/python@3.13/3.13.5/Frameworks/Python.framework/Versions/3.13/lib/python3.13/json/__init__.py", line 179, in dump for chunk in iterable: ^^^^^^^^ File "/opt/homebrew/Cellar/python@3.13/3.13.5/Frameworks/Python.framework/Versions/3.13/lib/python3.13/json/encoder.py", line 433, in _iterencode yield from _iterencode_dict(o, _current_indent_level) File "/opt/homebrew/Cellar/python@3.13/3.13.5/Frameworks/Python.framework/Versions/3.13/lib/python3.13/json/encoder.py", line 407, in _iterencode_dict yield from chunks File "/opt/homebrew/Cellar/python@3.13/3.13.5/Frameworks/Python.framework/Versions/3.13/lib/python3.13/json/encoder.py", line 440, in _iterencode o = _default(o) File "/opt/homebrew/Cellar/python@3.13/3.13.5/Frameworks/Python.framework/Versions/3.13/lib/python3.13/json/encoder.py", line 180, in default raise TypeError(f'Object of type {o.__class__.__name__} ' f'is not JSON serializable') TypeError: Object of type int64 is not JSON serializable
2025-08-20 20:26:54,689 [INFO] ‚úÖüìÅ Loop-4: Found result.json. Verifying...
2025-08-20 20:26:54,689 [INFO] ü§ñ Loop-4: Getting next step from LLM. Attempt 1
2025-08-20 20:27:04,329 [INFO] üíª Loop-5: Running LLM-generated code.
2025-08-20 20:27:05,161 [ERROR] ‚ùåüíª Loop-5: Code execution failed: Traceback (most recent call last): File "/Users/aditiprasad/Desktop/tds-2/uploads/e8c70522-ee5b-42be-ba62-46e029d05ffc/script.py", line 69, in <module> json.dump(result, f) ~~~~~~~~~^^^^^^^^^^^ File "/opt/homebrew/Cellar/python@3.13/3.13.5/Frameworks/Python.framework/Versions/3.13/lib/python3.13/json/__init__.py", line 179, in dump for chunk in iterable: ^^^^^^^^ File "/opt/homebrew/Cellar/python@3.13/3.13.5/Frameworks/Python.framework/Versions/3.13/lib/python3.13/json/encoder.py", line 433, in _iterencode yield from _iterencode_dict(o, _current_indent_level) File "/opt/homebrew/Cellar/python@3.13/3.13.5/Frameworks/Python.framework/Versions/3.13/lib/python3.13/json/encoder.py", line 407, in _iterencode_dict yield from chunks File "/opt/homebrew/Cellar/python@3.13/3.13.5/Frameworks/Python.framework/Versions/3.13/lib/python3.13/json/encoder.py", line 440, in _iterencode o = _default(o) File "/opt/homebrew/Cellar/python@3.13/3.13.5/Frameworks/Python.framework/Versions/3.13/lib/python3.13/json/encoder.py", line 180, in default raise TypeError(f'Object of type {o.__class__.__name__} ' f'is not JSON serializable') TypeError: Object of type int64 is not JSON serializable
2025-08-20 20:27:05,162 [INFO] ‚úÖüìÅ Loop-5: Found result.json. Verifying...
2025-08-20 20:27:05,162 [INFO] ü§ñ Loop-5: Getting next step from LLM. Attempt 1
2025-08-20 20:27:15,287 [ERROR] ‚ùå Error reading final result.json: Expecting value: line 1 column 72 (char 71)
