2025-08-20 20:35:11,216 [INFO] Step-1: Folder created: /Users/aditiprasad/Desktop/tds-2/uploads/72a38f9c-a9b6-4a73-9fec-0cc301a95bd1
2025-08-20 20:35:11,218 [INFO] Using Python executable: /Users/aditiprasad/Desktop/tds-2/venv/bin/python3
2025-08-20 20:35:11,218 [INFO] ü§ñ Step-1: Getting initial code from LLM. Attempt 1
2025-08-20 20:35:29,347 [INFO] ü§ñ Step-1: Successfully parsed response from LLM.
2025-08-20 20:35:29,348 [INFO] üíª Loop-1: Running LLM-generated code.
2025-08-20 20:35:30,149 [ERROR] ‚ùåüíª Loop-1: Code execution failed: Traceback (most recent call last): File "/Users/aditiprasad/Desktop/tds-2/venv/lib/python3.13/site-packages/pandas/core/indexes/base.py", line 3812, in get_loc return self._engine.get_loc(casted_key) ~~~~~~~~~~~~~~~~~~~~^^^^^^^^^^^^ File "pandas/_libs/index.pyx", line 167, in pandas._libs.index.IndexEngine.get_loc File "pandas/_libs/index.pyx", line 196, in pandas._libs.index.IndexEngine.get_loc File "pandas/_libs/hashtable_class_helper.pxi", line 7088, in pandas._libs.hashtable.PyObjectHashTable.get_item File "pandas/_libs/hashtable_class_helper.pxi", line 7096, in pandas._libs.hashtable.PyObjectHashTable.get_item KeyError: 'Temperature_C' The above exception was the direct cause of the following exception: Traceback (most recent call last): File "/Users/aditiprasad/Desktop/tds-2/uploads/72a38f9c-a9b6-4a73-9fec-0cc301a95bd1/script.py", line 11, in <module> avg_temp = df['Temperature_C'].mean() ~~^^^^^^^^^^^^^^^^^ File "/Users/aditiprasad/Desktop/tds-2/venv/lib/python3.13/site-packages/pandas/core/frame.py", line 4107, in __getitem__ indexer = self.columns.get_loc(key) File "/Users/aditiprasad/Desktop/tds-2/venv/lib/python3.13/site-packages/pandas/core/indexes/base.py", line 3819, in get_loc raise KeyError(key) from err KeyError: 'Temperature_C'
2025-08-20 20:35:30,149 [INFO] ü§ñ Loop-1: Getting next step from LLM. Attempt 1
2025-08-20 20:35:40,936 [INFO] üíª Loop-2: Running LLM-generated code.
2025-08-20 20:35:41,634 [ERROR] ‚ùåüíª Loop-2: Code execution failed: Traceback (most recent call last): File "/Users/aditiprasad/Desktop/tds-2/venv/lib/python3.13/site-packages/pandas/core/indexes/base.py", line 3812, in get_loc return self._engine.get_loc(casted_key) ~~~~~~~~~~~~~~~~~~~~^^^^^^^^^^^^ File "pandas/_libs/index.pyx", line 167, in pandas._libs.index.IndexEngine.get_loc File "pandas/_libs/index.pyx", line 196, in pandas._libs.index.IndexEngine.get_loc File "pandas/_libs/hashtable_class_helper.pxi", line 7088, in pandas._libs.hashtable.PyObjectHashTable.get_item File "pandas/_libs/hashtable_class_helper.pxi", line 7096, in pandas._libs.hashtable.PyObjectHashTable.get_item KeyError: 'temperature' The above exception was the direct cause of the following exception: Traceback (most recent call last): File "/Users/aditiprasad/Desktop/tds-2/uploads/72a38f9c-a9b6-4a73-9fec-0cc301a95bd1/script.py", line 11, in <module> avg_temp = df['temperature'].mean() ~~^^^^^^^^^^^^^^^ File "/Users/aditiprasad/Desktop/tds-2/venv/lib/python3.13/site-packages/pandas/core/frame.py", line 4107, in __getitem__ indexer = self.columns.get_loc(key) File "/Users/aditiprasad/Desktop/tds-2/venv/lib/python3.13/site-packages/pandas/core/indexes/base.py", line 3819, in get_loc raise KeyError(key) from err KeyError: 'temperature'
2025-08-20 20:35:41,635 [INFO] ü§ñ Loop-2: Getting next step from LLM. Attempt 1
2025-08-20 20:35:53,142 [INFO] üíª Loop-3: Running LLM-generated code.
2025-08-20 20:35:54,174 [ERROR] ‚ùåüíª Loop-3: Code execution failed: Traceback (most recent call last): File "/Users/aditiprasad/Desktop/tds-2/uploads/72a38f9c-a9b6-4a73-9fec-0cc301a95bd1/script.py", line 66, in <module> json.dump(result, f) ~~~~~~~~~^^^^^^^^^^^ File "/opt/homebrew/Cellar/python@3.13/3.13.5/Frameworks/Python.framework/Versions/3.13/lib/python3.13/json/__init__.py", line 179, in dump for chunk in iterable: ^^^^^^^^ File "/opt/homebrew/Cellar/python@3.13/3.13.5/Frameworks/Python.framework/Versions/3.13/lib/python3.13/json/encoder.py", line 433, in _iterencode yield from _iterencode_dict(o, _current_indent_level) File "/opt/homebrew/Cellar/python@3.13/3.13.5/Frameworks/Python.framework/Versions/3.13/lib/python3.13/json/encoder.py", line 407, in _iterencode_dict yield from chunks File "/opt/homebrew/Cellar/python@3.13/3.13.5/Frameworks/Python.framework/Versions/3.13/lib/python3.13/json/encoder.py", line 440, in _iterencode o = _default(o) File "/opt/homebrew/Cellar/python@3.13/3.13.5/Frameworks/Python.framework/Versions/3.13/lib/python3.13/json/encoder.py", line 180, in default raise TypeError(f'Object of type {o.__class__.__name__} ' f'is not JSON serializable') TypeError: Object of type int64 is not JSON serializable
2025-08-20 20:35:54,174 [INFO] ‚úÖüìÅ Loop-3: Found result.json. Verifying...
2025-08-20 20:35:54,175 [INFO] ü§ñ Loop-3: Getting next step from LLM. Attempt 1
2025-08-20 20:38:27,980 [INFO] üíª Loop-4: Running LLM-generated code.
2025-08-20 20:38:28,882 [ERROR] ‚ùåüíª Loop-4: Code execution failed: Traceback (most recent call last): File "/Users/aditiprasad/Desktop/tds-2/uploads/72a38f9c-a9b6-4a73-9fec-0cc301a95bd1/script.py", line 66, in <module> json.dump(result, f) ~~~~~~~~~^^^^^^^^^^^ File "/opt/homebrew/Cellar/python@3.13/3.13.5/Frameworks/Python.framework/Versions/3.13/lib/python3.13/json/__init__.py", line 179, in dump for chunk in iterable: ^^^^^^^^ File "/opt/homebrew/Cellar/python@3.13/3.13.5/Frameworks/Python.framework/Versions/3.13/lib/python3.13/json/encoder.py", line 433, in _iterencode yield from _iterencode_dict(o, _current_indent_level) File "/opt/homebrew/Cellar/python@3.13/3.13.5/Frameworks/Python.framework/Versions/3.13/lib/python3.13/json/encoder.py", line 407, in _iterencode_dict yield from chunks File "/opt/homebrew/Cellar/python@3.13/3.13.5/Frameworks/Python.framework/Versions/3.13/lib/python3.13/json/encoder.py", line 440, in _iterencode o = _default(o) File "/opt/homebrew/Cellar/python@3.13/3.13.5/Frameworks/Python.framework/Versions/3.13/lib/python3.13/json/encoder.py", line 180, in default raise TypeError(f'Object of type {o.__class__.__name__} ' f'is not JSON serializable') TypeError: Object of type int64 is not JSON serializable
2025-08-20 20:38:28,883 [INFO] ‚úÖüìÅ Loop-4: Found result.json. Verifying...
2025-08-20 20:38:28,883 [INFO] ü§ñ Loop-4: Getting next step from LLM. Attempt 1
2025-08-20 20:38:37,417 [INFO] üíª Loop-5: Running LLM-generated code.
2025-08-20 20:38:38,356 [INFO] ‚úÖüíª Loop-5: Code executed successfully.
2025-08-20 20:38:38,356 [INFO] ‚úÖüìÅ Loop-5: Found result.json. Verifying...
2025-08-20 20:38:38,357 [INFO] ü§ñ Loop-5: Getting next step from LLM. Attempt 1
2025-08-20 20:38:42,252 [INFO] ‚úÖ Final result found. Returning to user.
