2025-08-20 20:19:02,748 [INFO] Step-1: Folder created: /Users/aditiprasad/Desktop/tds-2/uploads/5b93dff6-9b66-46f0-a65b-dc4667039c18
2025-08-20 20:19:02,752 [INFO] Using Python executable: /Users/aditiprasad/Desktop/tds-2/venv/bin/python3
2025-08-20 20:19:02,752 [INFO] ü§ñ Step-1: Getting initial code from LLM. Attempt 1
2025-08-20 20:19:18,095 [INFO] ü§ñ Step-1: Successfully parsed response from LLM.
2025-08-20 20:19:18,095 [INFO] üíª Loop-1: Running LLM-generated code.
2025-08-20 20:19:19,043 [ERROR] ‚ùåüíª Loop-1: Code execution failed: Traceback (most recent call last): File "/Users/aditiprasad/Desktop/tds-2/venv/lib/python3.13/site-packages/pandas/core/indexes/base.py", line 3812, in get_loc return self._engine.get_loc(casted_key) ~~~~~~~~~~~~~~~~~~~~^^^^^^^^^^^^ File "pandas/_libs/index.pyx", line 167, in pandas._libs.index.IndexEngine.get_loc File "pandas/_libs/index.pyx", line 196, in pandas._libs.index.IndexEngine.get_loc File "pandas/_libs/hashtable_class_helper.pxi", line 7088, in pandas._libs.hashtable.PyObjectHashTable.get_item File "pandas/_libs/hashtable_class_helper.pxi", line 7096, in pandas._libs.hashtable.PyObjectHashTable.get_item KeyError: 'Order Date' The above exception was the direct cause of the following exception: Traceback (most recent call last): File "/Users/aditiprasad/Desktop/tds-2/uploads/5b93dff6-9b66-46f0-a65b-dc4667039c18/script.py", line 12, in <module> df['Order Date'] = pd.to_datetime(df['Order Date']) ~~^^^^^^^^^^^^^^ File "/Users/aditiprasad/Desktop/tds-2/venv/lib/python3.13/site-packages/pandas/core/frame.py", line 4107, in __getitem__ indexer = self.columns.get_loc(key) File "/Users/aditiprasad/Desktop/tds-2/venv/lib/python3.13/site-packages/pandas/core/indexes/base.py", line 3819, in get_loc raise KeyError(key) from err KeyError: 'Order Date'
2025-08-20 20:19:19,043 [INFO] ü§ñ Loop-1: Getting next step from LLM. Attempt 1
2025-08-20 20:19:27,328 [INFO] üíª Loop-2: Running LLM-generated code.
2025-08-20 20:19:27,960 [ERROR] ‚ùåüíª Loop-2: Code execution failed: Traceback (most recent call last): File "/Users/aditiprasad/Desktop/tds-2/venv/lib/python3.13/site-packages/pandas/core/indexes/base.py", line 3812, in get_loc return self._engine.get_loc(casted_key) ~~~~~~~~~~~~~~~~~~~~^^^^^^^^^^^^ File "pandas/_libs/index.pyx", line 167, in pandas._libs.index.IndexEngine.get_loc File "pandas/_libs/index.pyx", line 196, in pandas._libs.index.IndexEngine.get_loc File "pandas/_libs/hashtable_class_helper.pxi", line 7088, in pandas._libs.hashtable.PyObjectHashTable.get_item File "pandas/_libs/hashtable_class_helper.pxi", line 7096, in pandas._libs.hashtable.PyObjectHashTable.get_item KeyError: 'OrderDate' The above exception was the direct cause of the following exception: Traceback (most recent call last): File "/Users/aditiprasad/Desktop/tds-2/uploads/5b93dff6-9b66-46f0-a65b-dc4667039c18/script.py", line 12, in <module> df['OrderDate'] = pd.to_datetime(df['OrderDate']) ~~^^^^^^^^^^^^^ File "/Users/aditiprasad/Desktop/tds-2/venv/lib/python3.13/site-packages/pandas/core/frame.py", line 4107, in __getitem__ indexer = self.columns.get_loc(key) File "/Users/aditiprasad/Desktop/tds-2/venv/lib/python3.13/site-packages/pandas/core/indexes/base.py", line 3819, in get_loc raise KeyError(key) from err KeyError: 'OrderDate'
2025-08-20 20:19:27,961 [INFO] ü§ñ Loop-2: Getting next step from LLM. Attempt 1
2025-08-20 20:19:37,227 [INFO] üíª Loop-3: Running LLM-generated code.
2025-08-20 20:19:37,940 [ERROR] ‚ùåüíª Loop-3: Code execution failed: Traceback (most recent call last): File "/Users/aditiprasad/Desktop/tds-2/venv/lib/python3.13/site-packages/pandas/core/indexes/base.py", line 3812, in get_loc return self._engine.get_loc(casted_key) ~~~~~~~~~~~~~~~~~~~~^^^^^^^^^^^^ File "pandas/_libs/index.pyx", line 167, in pandas._libs.index.IndexEngine.get_loc File "pandas/_libs/index.pyx", line 196, in pandas._libs.index.IndexEngine.get_loc File "pandas/_libs/hashtable_class_helper.pxi", line 7088, in pandas._libs.hashtable.PyObjectHashTable.get_item File "pandas/_libs/hashtable_class_helper.pxi", line 7096, in pandas._libs.hashtable.PyObjectHashTable.get_item KeyError: 'Order Date' The above exception was the direct cause of the following exception: Traceback (most recent call last): File "/Users/aditiprasad/Desktop/tds-2/uploads/5b93dff6-9b66-46f0-a65b-dc4667039c18/script.py", line 12, in <module> df['Order Date'] = pd.to_datetime(df['Order Date']) ~~^^^^^^^^^^^^^^ File "/Users/aditiprasad/Desktop/tds-2/venv/lib/python3.13/site-packages/pandas/core/frame.py", line 4107, in __getitem__ indexer = self.columns.get_loc(key) File "/Users/aditiprasad/Desktop/tds-2/venv/lib/python3.13/site-packages/pandas/core/indexes/base.py", line 3819, in get_loc raise KeyError(key) from err KeyError: 'Order Date'
2025-08-20 20:19:37,941 [INFO] ü§ñ Loop-3: Getting next step from LLM. Attempt 1
2025-08-20 20:19:48,058 [INFO] üíª Loop-4: Running LLM-generated code.
2025-08-20 20:19:48,780 [ERROR] ‚ùåüíª Loop-4: Code execution failed: err KeyError: 'Order Date' During handling of the above exception, another exception occurred: Traceback (most recent call last): File "/Users/aditiprasad/Desktop/tds-2/venv/lib/python3.13/site-packages/pandas/core/indexes/base.py", line 3812, in get_loc return self._engine.get_loc(casted_key) ~~~~~~~~~~~~~~~~~~~~^^^^^^^^^^^^ File "pandas/_libs/index.pyx", line 167, in pandas._libs.index.IndexEngine.get_loc File "pandas/_libs/index.pyx", line 196, in pandas._libs.index.IndexEngine.get_loc File "pandas/_libs/hashtable_class_helper.pxi", line 7088, in pandas._libs.hashtable.PyObjectHashTable.get_item File "pandas/_libs/hashtable_class_helper.pxi", line 7096, in pandas._libs.hashtable.PyObjectHashTable.get_item KeyError: 'OrderDate' The above exception was the direct cause of the following exception: Traceback (most recent call last): File "/Users/aditiprasad/Desktop/tds-2/uploads/5b93dff6-9b66-46f0-a65b-dc4667039c18/script.py", line 15, in <module> df['OrderDate'] = pd.to_datetime(df['OrderDate']) ~~^^^^^^^^^^^^^ File "/Users/aditiprasad/Desktop/tds-2/venv/lib/python3.13/site-packages/pandas/core/frame.py", line 4107, in __getitem__ indexer = self.columns.get_loc(key) File "/Users/aditiprasad/Desktop/tds-2/venv/lib/python3.13/site-packages/pandas/core/indexes/base.py", line 3819, in get_loc raise KeyError(key) from err KeyError: 'OrderDate'
2025-08-20 20:19:48,780 [INFO] ü§ñ Loop-4: Getting next step from LLM. Attempt 1
2025-08-20 20:19:58,231 [INFO] üíª Loop-5: Running LLM-generated code.
2025-08-20 20:19:58,863 [ERROR] ‚ùåüíª Loop-5: Code execution failed: Traceback (most recent call last): File "/Users/aditiprasad/Desktop/tds-2/venv/lib/python3.13/site-packages/pandas/core/indexes/base.py", line 3812, in get_loc return self._engine.get_loc(casted_key) ~~~~~~~~~~~~~~~~~~~~^^^^^^^^^^^^ File "pandas/_libs/index.pyx", line 167, in pandas._libs.index.IndexEngine.get_loc File "pandas/_libs/index.pyx", line 196, in pandas._libs.index.IndexEngine.get_loc File "pandas/_libs/hashtable_class_helper.pxi", line 7088, in pandas._libs.hashtable.PyObjectHashTable.get_item File "pandas/_libs/hashtable_class_helper.pxi", line 7096, in pandas._libs.hashtable.PyObjectHashTable.get_item KeyError: 'OrderDate' The above exception was the direct cause of the following exception: Traceback (most recent call last): File "/Users/aditiprasad/Desktop/tds-2/uploads/5b93dff6-9b66-46f0-a65b-dc4667039c18/script.py", line 13, in <module> df[date_col] = pd.to_datetime(df[date_col]) ~~^^^^^^^^^^ File "/Users/aditiprasad/Desktop/tds-2/venv/lib/python3.13/site-packages/pandas/core/frame.py", line 4107, in __getitem__ indexer = self.columns.get_loc(key) File "/Users/aditiprasad/Desktop/tds-2/venv/lib/python3.13/site-packages/pandas/core/indexes/base.py", line 3819, in get_loc raise KeyError(key) from err KeyError: 'OrderDate'
2025-08-20 20:19:58,864 [INFO] ü§ñ Loop-5: Getting next step from LLM. Attempt 1
