2025-08-20 20:33:25,417 [INFO] Step-1: Folder created: /Users/aditiprasad/Desktop/tds-2/uploads/6969f1fe-542f-4ffe-8544-185ef16b52b3
2025-08-20 20:33:25,427 [INFO] Using Python executable: /Users/aditiprasad/Desktop/tds-2/venv/bin/python3
2025-08-20 20:33:25,427 [INFO] ü§ñ Step-1: Getting initial code from LLM. Attempt 1
2025-08-20 20:33:53,951 [INFO] ü§ñ Step-1: Successfully parsed response from LLM.
2025-08-20 20:33:53,951 [INFO] üíª Loop-1: Running LLM-generated code.
2025-08-20 20:33:54,748 [ERROR] ‚ùåüíª Loop-1: Code execution failed: Traceback (most recent call last): File "/Users/aditiprasad/Desktop/tds-2/venv/lib/python3.13/site-packages/pandas/core/indexes/base.py", line 3812, in get_loc return self._engine.get_loc(casted_key) ~~~~~~~~~~~~~~~~~~~~^^^^^^^^^^^^ File "pandas/_libs/index.pyx", line 167, in pandas._libs.index.IndexEngine.get_loc File "pandas/_libs/index.pyx", line 196, in pandas._libs.index.IndexEngine.get_loc File "pandas/_libs/hashtable_class_helper.pxi", line 7088, in pandas._libs.hashtable.PyObjectHashTable.get_item File "pandas/_libs/hashtable_class_helper.pxi", line 7096, in pandas._libs.hashtable.PyObjectHashTable.get_item KeyError: 'Sales' The above exception was the direct cause of the following exception: Traceback (most recent call last): File "/Users/aditiprasad/Desktop/tds-2/uploads/6969f1fe-542f-4ffe-8544-185ef16b52b3/script.py", line 18, in <module> total_sales = df['Sales'].sum() ~~^^^^^^^^^ File "/Users/aditiprasad/Desktop/tds-2/venv/lib/python3.13/site-packages/pandas/core/frame.py", line 4107, in __getitem__ indexer = self.columns.get_loc(key) File "/Users/aditiprasad/Desktop/tds-2/venv/lib/python3.13/site-packages/pandas/core/indexes/base.py", line 3819, in get_loc raise KeyError(key) from err KeyError: 'Sales'
2025-08-20 20:33:54,748 [INFO] ü§ñ Loop-1: Getting next step from LLM. Attempt 1
2025-08-20 20:34:03,886 [INFO] üíª Loop-2: Running LLM-generated code.
2025-08-20 20:34:04,490 [ERROR] ‚ùåüíª Loop-2: Code execution failed: Traceback (most recent call last): File "/Users/aditiprasad/Desktop/tds-2/venv/lib/python3.13/site-packages/pandas/core/indexes/base.py", line 3812, in get_loc return self._engine.get_loc(casted_key) ~~~~~~~~~~~~~~~~~~~~^^^^^^^^^^^^ File "pandas/_libs/index.pyx", line 167, in pandas._libs.index.IndexEngine.get_loc File "pandas/_libs/index.pyx", line 196, in pandas._libs.index.IndexEngine.get_loc File "pandas/_libs/hashtable_class_helper.pxi", line 7088, in pandas._libs.hashtable.PyObjectHashTable.get_item File "pandas/_libs/hashtable_class_helper.pxi", line 7096, in pandas._libs.hashtable.PyObjectHashTable.get_item KeyError: 'Total' The above exception was the direct cause of the following exception: Traceback (most recent call last): File "/Users/aditiprasad/Desktop/tds-2/uploads/6969f1fe-542f-4ffe-8544-185ef16b52b3/script.py", line 18, in <module> total_sales = df['Total'].sum() ~~^^^^^^^^^ File "/Users/aditiprasad/Desktop/tds-2/venv/lib/python3.13/site-packages/pandas/core/frame.py", line 4107, in __getitem__ indexer = self.columns.get_loc(key) File "/Users/aditiprasad/Desktop/tds-2/venv/lib/python3.13/site-packages/pandas/core/indexes/base.py", line 3819, in get_loc raise KeyError(key) from err KeyError: 'Total'
2025-08-20 20:34:04,490 [INFO] ü§ñ Loop-2: Getting next step from LLM. Attempt 1
2025-08-20 20:34:20,271 [INFO] üíª Loop-3: Running LLM-generated code.
2025-08-20 20:34:20,957 [ERROR] ‚ùåüíª Loop-3: Code execution failed: Traceback (most recent call last): File "/Users/aditiprasad/Desktop/tds-2/venv/lib/python3.13/site-packages/pandas/core/indexes/base.py", line 3812, in get_loc return self._engine.get_loc(casted_key) ~~~~~~~~~~~~~~~~~~~~^^^^^^^^^^^^ File "pandas/_libs/index.pyx", line 167, in pandas._libs.index.IndexEngine.get_loc File "pandas/_libs/index.pyx", line 196, in pandas._libs.index.IndexEngine.get_loc File "pandas/_libs/hashtable_class_helper.pxi", line 7088, in pandas._libs.hashtable.PyObjectHashTable.get_item File "pandas/_libs/hashtable_class_helper.pxi", line 7096, in pandas._libs.hashtable.PyObjectHashTable.get_item KeyError: 'Total' The above exception was the direct cause of the following exception: Traceback (most recent call last): File "/Users/aditiprasad/Desktop/tds-2/uploads/6969f1fe-542f-4ffe-8544-185ef16b52b3/script.py", line 18, in <module> total_sales = df['Total'].sum() ~~^^^^^^^^^ File "/Users/aditiprasad/Desktop/tds-2/venv/lib/python3.13/site-packages/pandas/core/frame.py", line 4107, in __getitem__ indexer = self.columns.get_loc(key) File "/Users/aditiprasad/Desktop/tds-2/venv/lib/python3.13/site-packages/pandas/core/indexes/base.py", line 3819, in get_loc raise KeyError(key) from err KeyError: 'Total'
2025-08-20 20:34:20,957 [INFO] ü§ñ Loop-3: Getting next step from LLM. Attempt 1
2025-08-20 20:34:36,858 [INFO] üíª Loop-4: Running LLM-generated code.
2025-08-20 20:34:37,636 [ERROR] ‚ùåüíª Loop-4: Code execution failed: Traceback (most recent call last): File "/Users/aditiprasad/Desktop/tds-2/venv/lib/python3.13/site-packages/pandas/core/indexes/base.py", line 3812, in get_loc return self._engine.get_loc(casted_key) ~~~~~~~~~~~~~~~~~~~~^^^^^^^^^^^^ File "pandas/_libs/index.pyx", line 167, in pandas._libs.index.IndexEngine.get_loc File "pandas/_libs/index.pyx", line 196, in pandas._libs.index.IndexEngine.get_loc File "pandas/_libs/hashtable_class_helper.pxi", line 7088, in pandas._libs.hashtable.PyObjectHashTable.get_item File "pandas/_libs/hashtable_class_helper.pxi", line 7096, in pandas._libs.hashtable.PyObjectHashTable.get_item KeyError: 'Total' The above exception was the direct cause of the following exception: Traceback (most recent call last): File "/Users/aditiprasad/Desktop/tds-2/uploads/6969f1fe-542f-4ffe-8544-185ef16b52b3/script.py", line 19, in <module> total_sales = df['Total'].sum() ~~^^^^^^^^^ File "/Users/aditiprasad/Desktop/tds-2/venv/lib/python3.13/site-packages/pandas/core/frame.py", line 4107, in __getitem__ indexer = self.columns.get_loc(key) File "/Users/aditiprasad/Desktop/tds-2/venv/lib/python3.13/site-packages/pandas/core/indexes/base.py", line 3819, in get_loc raise KeyError(key) from err KeyError: 'Total'
2025-08-20 20:34:37,637 [INFO] ü§ñ Loop-4: Getting next step from LLM. Attempt 1
2025-08-20 20:34:51,202 [INFO] üíª Loop-5: Running LLM-generated code.
2025-08-20 20:34:52,073 [ERROR] ‚ùåüíª Loop-5: Code execution failed: Traceback (most recent call last): File "/Users/aditiprasad/Desktop/tds-2/venv/lib/python3.13/site-packages/pandas/core/indexes/base.py", line 3812, in get_loc return self._engine.get_loc(casted_key) ~~~~~~~~~~~~~~~~~~~~^^^^^^^^^^^^ File "pandas/_libs/index.pyx", line 167, in pandas._libs.index.IndexEngine.get_loc File "pandas/_libs/index.pyx", line 196, in pandas._libs.index.IndexEngine.get_loc File "pandas/_libs/hashtable_class_helper.pxi", line 7088, in pandas._libs.hashtable.PyObjectHashTable.get_item File "pandas/_libs/hashtable_class_helper.pxi", line 7096, in pandas._libs.hashtable.PyObjectHashTable.get_item KeyError: 'Total' The above exception was the direct cause of the following exception: Traceback (most recent call last): File "/Users/aditiprasad/Desktop/tds-2/uploads/6969f1fe-542f-4ffe-8544-185ef16b52b3/script.py", line 19, in <module> total_sales = df['Total'].sum() ~~^^^^^^^^^ File "/Users/aditiprasad/Desktop/tds-2/venv/lib/python3.13/site-packages/pandas/core/frame.py", line 4107, in __getitem__ indexer = self.columns.get_loc(key) File "/Users/aditiprasad/Desktop/tds-2/venv/lib/python3.13/site-packages/pandas/core/indexes/base.py", line 3819, in get_loc raise KeyError(key) from err KeyError: 'Total'
2025-08-20 20:34:52,074 [INFO] ü§ñ Loop-5: Getting next step from LLM. Attempt 1
